2025-08-01 12:19:14,402 - __main__ - INFO - Log file created: logs/content_generation_20250801_121914_visiting_goa.log
2025-08-01 12:19:14,402 - __main__ - INFO - Original idea: visiting goa
2025-08-01 12:19:14,403 - __main__ - INFO - Current working directory: C:\mobile app\social_media_content_generator
2025-08-01 12:19:14,403 - __main__ - INFO - Loading environment variables...
2025-08-01 12:19:14,405 - __main__ - INFO - Environment variables loaded:
2025-08-01 12:19:14,405 - __main__ - INFO - OPENAI_API_KEY present: False
2025-08-01 12:19:14,406 - __main__ - INFO - OPENROUTER_API_KEY present: True
2025-08-01 12:19:14,406 - __main__ - INFO - Starting Social Media Content Generator
2025-08-01 12:19:14,407 - __main__ - INFO - Initializing SocialMediaContentGenerator
2025-08-01 12:19:14,408 - __main__ - INFO - Simple database logger initialized successfully
2025-08-01 12:19:14,409 - __main__ - INFO - Database logger initialized successfully
2025-08-01 12:19:14,409 - __main__ - INFO - Initializing SocialMediaCrew
2025-08-01 12:19:14,410 - __main__ - INFO - Simple database logger initialized successfully
2025-08-01 12:19:14,410 - __main__ - INFO - Database logger initialized in crew
2025-08-01 12:19:14,893 - __main__ - INFO - Language model (OpenRouter) configured successfully with model: openai/gpt-3.5-turbo
2025-08-01 12:19:14,893 - __main__ - INFO - Model configurations from config:
2025-08-01 12:19:14,894 - __main__ - INFO -   content_strategist: openai/gpt-3.5-turbo (temp: 0.7)
2025-08-01 12:19:14,894 - __main__ - INFO -   content_writer: openai/gpt-3.5-turbo (temp: 0.8)
2025-08-01 12:19:14,894 - __main__ - INFO -   hashtag_specialist: openai/gpt-3.5-turbo (temp: 0.6)
2025-08-01 12:19:14,894 - __main__ - INFO -   visual_designer: openai/gpt-3.5-turbo (temp: 0.7)
2025-08-01 12:19:14,894 - __main__ - INFO - Validating setup
2025-08-01 12:19:14,894 - __main__ - INFO - SocialMediaContentGenerator initialized successfully
2025-08-01 12:19:19,617 - __main__ - INFO - Selected platforms: instagram
2025-08-01 12:19:28,529 - __main__ - INFO - Selected tones: ['friendly']
2025-08-01 12:20:55,642 - __main__ - INFO - Selected audiences: ['young adults (20-29)']
2025-08-01 12:20:56,287 - __main__ - ERROR - Failed to start generation session: Failed to create session record
2025-08-01 12:20:56,288 - __main__ - INFO - Started database logging session: None
2025-08-01 12:20:56,290 - __main__ - INFO - Generating content for platform: instagram
2025-08-01 12:20:56,293 - __main__ - INFO - ==================================================
2025-08-01 12:20:56,294 - __main__ - INFO - Crew Execution Started
2025-08-01 12:20:56,294 - __main__ - INFO - Crew ID: 20250801-122056
2025-08-01 12:20:56,295 - __main__ - INFO - ==================================================
2025-08-01 12:20:56,296 - __main__ - INFO - Content Strategist Agent: Started
2025-08-01 12:20:56,296 - __main__ - WARNING - No active session. Skipping agent execution logging.
2025-08-01 12:20:56,298 - __main__ - ERROR - Content Generation Error
2025-08-01 12:20:56,298 - __main__ - ERROR - Error details: 1 validation error for Agent
tools.0
  Input should be a valid dictionary or instance of BaseTool [type=model_type, input_value=StructuredTool(name='url_... at 0x000002136B3CC2C0>), input_type=StructuredTool]
    For further information visit https://errors.pydantic.dev/2.11/v/model_type
Traceback (most recent call last):
  File "C:\mobile app\social_media_content_generator\src\crew.py", line 211, in run
    strategy_result = self._execute_strategist_task(idea, platform, tones, audiences)
  File "C:\mobile app\social_media_content_generator\src\crew.py", line 639, in _execute_strategist_task
    content_strategist = ContentStrategist.create(strategist_llm)
  File "C:\mobile app\social_media_content_generator\src\agents\content_strategist.py", line 21, in create
    return Agent(
        role='Content Strategist',
    ...<6 lines>...
        verbose=True
    )
  File "C:\mobile app\social_media_content_generator\.venv\Lib\site-packages\pydantic\main.py", line 253, in __init__
    validated_self = self.__pydantic_validator__.validate_python(data, self_instance=self)
pydantic_core._pydantic_core.ValidationError: 1 validation error for Agent
tools.0
  Input should be a valid dictionary or instance of BaseTool [type=model_type, input_value=StructuredTool(name='url_... at 0x000002136B3CC2C0>), input_type=StructuredTool]
    For further information visit https://errors.pydantic.dev/2.11/v/model_type
2025-08-01 12:20:56,458 - __main__ - ERROR - API request failed: 400 Client Error: Bad Request for url: https://wwrnhbjkfnuhgjxanixy.supabase.co/rest/v1/error_logs
2025-08-01 12:20:56,460 - __main__ - ERROR - Failed to log user-facing error: 400 Client Error: Bad Request for url: https://wwrnhbjkfnuhgjxanixy.supabase.co/rest/v1/error_logs
2025-08-01 12:20:56,462 - __main__ - ERROR - Content generation failed: Content generation failed: 1 validation error for Agent
tools.0
  Input should be a valid dictionary or instance of BaseTool [type=model_type, input_value=StructuredTool(name='url_... at 0x000002136B3CC2C0>), input_type=StructuredTool]
    For further information visit https://errors.pydantic.dev/2.11/v/model_type
Traceback (most recent call last):
  File "C:\mobile app\social_media_content_generator\src\crew.py", line 211, in run
    strategy_result = self._execute_strategist_task(idea, platform, tones, audiences)
  File "C:\mobile app\social_media_content_generator\src\crew.py", line 639, in _execute_strategist_task
    content_strategist = ContentStrategist.create(strategist_llm)
  File "C:\mobile app\social_media_content_generator\src\agents\content_strategist.py", line 21, in create
    return Agent(
        role='Content Strategist',
    ...<6 lines>...
        verbose=True
    )
  File "C:\mobile app\social_media_content_generator\.venv\Lib\site-packages\pydantic\main.py", line 253, in __init__
    validated_self = self.__pydantic_validator__.validate_python(data, self_instance=self)
pydantic_core._pydantic_core.ValidationError: 1 validation error for Agent
tools.0
  Input should be a valid dictionary or instance of BaseTool [type=model_type, input_value=StructuredTool(name='url_... at 0x000002136B3CC2C0>), input_type=StructuredTool]
    For further information visit https://errors.pydantic.dev/2.11/v/model_type

During handling of the above exception, another exception occurred:

Traceback (most recent call last):
  File "C:\mobile app\social_media_content_generator\src\main.py", line 58, in generate_content
    result = self.crew.run(idea, platform, tones, audiences)
  File "C:\mobile app\social_media_content_generator\src\crew.py", line 472, in run
    raise Exception(f"Content generation failed: {str(e)}")
Exception: Content generation failed: 1 validation error for Agent
tools.0
  Input should be a valid dictionary or instance of BaseTool [type=model_type, input_value=StructuredTool(name='url_... at 0x000002136B3CC2C0>), input_type=StructuredTool]
    For further information visit https://errors.pydantic.dev/2.11/v/model_type
2025-08-01 12:20:56,615 - __main__ - ERROR - API request failed: 400 Client Error: Bad Request for url: https://wwrnhbjkfnuhgjxanixy.supabase.co/rest/v1/error_logs
2025-08-01 12:20:56,616 - __main__ - ERROR - Failed to log user-facing error: 400 Client Error: Bad Request for url: https://wwrnhbjkfnuhgjxanixy.supabase.co/rest/v1/error_logs
2025-08-01 12:20:56,617 - __main__ - WARNING - No active session to complete.
2025-08-01 12:20:56,619 - __main__ - ERROR - Failed to generate content for instagram: Content generation failed: Content generation failed: 1 validation error for Agent
tools.0
  Input should be a valid dictionary or instance of BaseTool [type=model_type, input_value=StructuredTool(name='url_... at 0x000002136B3CC2C0>), input_type=StructuredTool]
    For further information visit https://errors.pydantic.dev/2.11/v/model_type
2025-08-01 12:20:56,745 - __main__ - ERROR - API request failed: 400 Client Error: Bad Request for url: https://wwrnhbjkfnuhgjxanixy.supabase.co/rest/v1/error_logs
2025-08-01 12:20:56,747 - __main__ - ERROR - Failed to log user-facing error: 400 Client Error: Bad Request for url: https://wwrnhbjkfnuhgjxanixy.supabase.co/rest/v1/error_logs
2025-08-01 12:20:56,750 - __main__ - INFO - Content generation and display completed successfully
