2025-08-01 10:42:26,913 - __main__ - INFO - Log file created: logs/content_generation_20250801_104226_monday_fitness_motivation.log
2025-08-01 10:42:26,914 - __main__ - INFO - Original idea: monday fitness motivation
2025-08-01 10:42:26,914 - __main__ - INFO - Current working directory: C:\mobile app\social_media_content_generator
2025-08-01 10:42:26,914 - __main__ - INFO - Loading environment variables...
2025-08-01 10:42:26,916 - __main__ - INFO - Environment variables loaded:
2025-08-01 10:42:26,916 - __main__ - INFO - OPENAI_API_KEY present: False
2025-08-01 10:42:26,917 - __main__ - INFO - OPENROUTER_API_KEY present: True
2025-08-01 10:42:26,917 - __main__ - INFO - Starting Social Media Content Generator
2025-08-01 10:42:26,917 - __main__ - INFO - Initializing SocialMediaContentGenerator
2025-08-01 10:42:26,919 - __main__ - INFO - Simple database logger initialized successfully
2025-08-01 10:42:26,919 - __main__ - INFO - Database logger initialized successfully
2025-08-01 10:42:26,919 - __main__ - INFO - Initializing SocialMediaCrew
2025-08-01 10:42:26,921 - __main__ - INFO - Simple database logger initialized successfully
2025-08-01 10:42:26,921 - __main__ - INFO - Database logger initialized in crew
2025-08-01 10:42:27,405 - __main__ - INFO - Language model (OpenRouter) configured successfully with model: openai/gpt-3.5-turbo
2025-08-01 10:42:27,405 - __main__ - INFO - Model configurations from config:
2025-08-01 10:42:27,405 - __main__ - INFO -   content_strategist: openai/gpt-3.5-turbo (temp: 0.7)
2025-08-01 10:42:27,405 - __main__ - INFO -   content_writer: openai/gpt-3.5-turbo (temp: 0.8)
2025-08-01 10:42:27,405 - __main__ - INFO -   hashtag_specialist: openai/gpt-3.5-turbo (temp: 0.6)
2025-08-01 10:42:27,406 - __main__ - INFO -   visual_designer: openai/gpt-3.5-turbo (temp: 0.7)
2025-08-01 10:42:27,406 - __main__ - INFO - Validating setup
2025-08-01 10:42:27,406 - __main__ - INFO - SocialMediaContentGenerator initialized successfully
2025-08-01 10:42:33,909 - __main__ - INFO - Selected platforms: instagram
2025-08-01 10:42:47,561 - __main__ - INFO - Selected tones: ['casual']
2025-08-01 10:43:07,881 - __main__ - INFO - Selected audiences: ['young adults (20-29)']
2025-08-01 10:43:08,098 - __main__ - ERROR - Failed to start generation session: Failed to create session record
2025-08-01 10:43:08,100 - __main__ - INFO - Started database logging session: None
2025-08-01 10:43:08,100 - __main__ - INFO - Generating content for platform: instagram
2025-08-01 10:43:08,102 - __main__ - INFO - ==================================================
2025-08-01 10:43:08,102 - __main__ - INFO - Crew Execution Started
2025-08-01 10:43:08,102 - __main__ - INFO - Crew ID: 20250801-104308
2025-08-01 10:43:08,102 - __main__ - INFO - ==================================================
2025-08-01 10:43:08,104 - __main__ - INFO - Content Strategist Agent: Started
2025-08-01 10:43:08,104 - __main__ - WARNING - No active session. Skipping agent execution logging.
2025-08-01 10:43:08,106 - __main__ - ERROR - Content Generation Error
2025-08-01 10:43:08,106 - __main__ - ERROR - Error details: 1 validation error for Agent
tools.0
  Input should be a valid dictionary or instance of BaseTool [type=model_type, input_value=StructuredTool(name='url_... at 0x000001D86B1CC2C0>), input_type=StructuredTool]
    For further information visit https://errors.pydantic.dev/2.11/v/model_type
Traceback (most recent call last):
  File "C:\mobile app\social_media_content_generator\src\crew.py", line 211, in run
    strategy_result = self._execute_strategist_task(idea, platform, tones, audiences)
  File "C:\mobile app\social_media_content_generator\src\crew.py", line 639, in _execute_strategist_task
    content_strategist = ContentStrategist.create(strategist_llm)
  File "C:\mobile app\social_media_content_generator\src\agents\content_strategist.py", line 21, in create
    return Agent(
        role='Content Strategist',
    ...<6 lines>...
        verbose=True
    )
  File "C:\mobile app\social_media_content_generator\.venv\Lib\site-packages\pydantic\main.py", line 253, in __init__
    validated_self = self.__pydantic_validator__.validate_python(data, self_instance=self)
pydantic_core._pydantic_core.ValidationError: 1 validation error for Agent
tools.0
  Input should be a valid dictionary or instance of BaseTool [type=model_type, input_value=StructuredTool(name='url_... at 0x000001D86B1CC2C0>), input_type=StructuredTool]
    For further information visit https://errors.pydantic.dev/2.11/v/model_type
2025-08-01 10:43:08,268 - __main__ - ERROR - API request failed: 400 Client Error: Bad Request for url: https://wwrnhbjkfnuhgjxanixy.supabase.co/rest/v1/error_logs
2025-08-01 10:43:08,269 - __main__ - ERROR - Failed to log user-facing error: 400 Client Error: Bad Request for url: https://wwrnhbjkfnuhgjxanixy.supabase.co/rest/v1/error_logs
2025-08-01 10:43:08,271 - __main__ - ERROR - Content generation failed: Content generation failed: 1 validation error for Agent
tools.0
  Input should be a valid dictionary or instance of BaseTool [type=model_type, input_value=StructuredTool(name='url_... at 0x000001D86B1CC2C0>), input_type=StructuredTool]
    For further information visit https://errors.pydantic.dev/2.11/v/model_type
Traceback (most recent call last):
  File "C:\mobile app\social_media_content_generator\src\crew.py", line 211, in run
    strategy_result = self._execute_strategist_task(idea, platform, tones, audiences)
  File "C:\mobile app\social_media_content_generator\src\crew.py", line 639, in _execute_strategist_task
    content_strategist = ContentStrategist.create(strategist_llm)
  File "C:\mobile app\social_media_content_generator\src\agents\content_strategist.py", line 21, in create
    return Agent(
        role='Content Strategist',
    ...<6 lines>...
        verbose=True
    )
  File "C:\mobile app\social_media_content_generator\.venv\Lib\site-packages\pydantic\main.py", line 253, in __init__
    validated_self = self.__pydantic_validator__.validate_python(data, self_instance=self)
pydantic_core._pydantic_core.ValidationError: 1 validation error for Agent
tools.0
  Input should be a valid dictionary or instance of BaseTool [type=model_type, input_value=StructuredTool(name='url_... at 0x000001D86B1CC2C0>), input_type=StructuredTool]
    For further information visit https://errors.pydantic.dev/2.11/v/model_type

During handling of the above exception, another exception occurred:

Traceback (most recent call last):
  File "C:\mobile app\social_media_content_generator\src\main.py", line 58, in generate_content
    result = self.crew.run(idea, platform, tones, audiences)
  File "C:\mobile app\social_media_content_generator\src\crew.py", line 472, in run
    raise Exception(f"Content generation failed: {str(e)}")
Exception: Content generation failed: 1 validation error for Agent
tools.0
  Input should be a valid dictionary or instance of BaseTool [type=model_type, input_value=StructuredTool(name='url_... at 0x000001D86B1CC2C0>), input_type=StructuredTool]
    For further information visit https://errors.pydantic.dev/2.11/v/model_type
2025-08-01 10:43:08,393 - __main__ - ERROR - API request failed: 400 Client Error: Bad Request for url: https://wwrnhbjkfnuhgjxanixy.supabase.co/rest/v1/error_logs
2025-08-01 10:43:08,394 - __main__ - ERROR - Failed to log user-facing error: 400 Client Error: Bad Request for url: https://wwrnhbjkfnuhgjxanixy.supabase.co/rest/v1/error_logs
2025-08-01 10:43:08,395 - __main__ - WARNING - No active session to complete.
2025-08-01 10:43:08,397 - __main__ - ERROR - Failed to generate content for instagram: Content generation failed: Content generation failed: 1 validation error for Agent
tools.0
  Input should be a valid dictionary or instance of BaseTool [type=model_type, input_value=StructuredTool(name='url_... at 0x000001D86B1CC2C0>), input_type=StructuredTool]
    For further information visit https://errors.pydantic.dev/2.11/v/model_type
2025-08-01 10:43:08,548 - __main__ - ERROR - API request failed: 400 Client Error: Bad Request for url: https://wwrnhbjkfnuhgjxanixy.supabase.co/rest/v1/error_logs
2025-08-01 10:43:08,550 - __main__ - ERROR - Failed to log user-facing error: 400 Client Error: Bad Request for url: https://wwrnhbjkfnuhgjxanixy.supabase.co/rest/v1/error_logs
2025-08-01 10:43:08,551 - __main__ - INFO - Content generation and display completed successfully
